I'm sorry, but an uncaught exception occurred.

While running game code:
  File "game/script.rpy", line 25, in script
    Valp Zam "Лер, ты меня совсем не слушаешь. Что происходит?"
Exception: Sayer 'Valp' is not defined.

-- Full Traceback ------------------------------------------------------------

Full traceback:
  File "game/script.rpy", line 25, in script
    Valp Zam "Лер, ты меня совсем не слушаешь. Что происходит?"
  File "C:\Users\marakulina-u\Desktop\renpy-8.2.1-sdk\renpy\ast.py", line 2557, in execute
    Say.execute(self)
  File "C:\Users\marakulina-u\Desktop\renpy-8.2.1-sdk\renpy\ast.py", line 575, in execute
    who = eval_who(self.who, self.who_fast)
  File "C:\Users\marakulina-u\Desktop\renpy-8.2.1-sdk\renpy\ast.py", line 464, in eval_who
    raise Exception("Sayer '%s' is not defined." % who)
Exception: Sayer 'Valp' is not defined.

Windows-10-10.0.19045 AMD64
Ren'Py 8.2.1.24030407
Markiz 1.0
Sun Apr 14 11:56:20 2024
